Workbook

Sheet Отчет по марже
G1: не оплачено | H1: д
A3: комм | B3: Юнит | C3: Продукт | D3: Проект | E3: Площадка | G3: Открутка (с НДС) | H3: Открутка ( БЕЗ НДС) | J3: Комиссия | K3: Работы | L3: Расходы | M3: Маржа | N3: Менеджер МП | P3: Специалист | R3: Руководитель напр | S3: Руководитель проджект
A4: SF | B4: Маркетплейсы | C4: Маркетплейсы | D4: Лавка мастера | E4: Премия KPI | G4: 66202.86 | H4: =G4/1.22 -> 54264.639 | I4: 1 | K4: =ROUND(H4*I4,2) -> 54264.64 | M4: =J4+K4-L4 -> 54264.64 | N4: ФИО5 | O4: =M4*8% -> 4341.1712 | P4: ФИО1 | Q4: =M4*4% -> 2170.5856 | S4: ФИО4
A5: SF | B5: Маркетплейсы | C5: Маркетплейсы | D5: Лавка мастера | E5: Услуги по продвижению на маркетплейсах: Ozon | G5: 103700 | H5: =G5/1.22 -> 85000 | I5: 1 | K5: =ROUND(H5*I5,2) -> 85000 | M5: =J5+K5-L5 -> 85000 | N5: ФИО5 | O5: =M5*8% -> 6800 | P5: ФИО1 | Q5: =M5*4% -> 3400 | S5: ФИО4
A6: SF | B6: Маркетплейсы | C6: Маркетплейсы | D6: Холодильник.Ру / Шелковый путь | E6: Услуги по продвижению на маркетплейсах: Wildberries | G6: 360000 | H6: =G6/1.22 -> 295081.97 | I6: 1 | K6: =ROUND(H6*I6,2) -> 295081.97 | M6: =J6+K6-L6 -> 295081.97 | N6: ФИО5 | O6: =M6*8% -> 23606.558 | P6: ФИО1 | Q6: =M6*4% -> 11803.279 | S6: ФИО4
A7: SF | B7: Маркетплейсы | C7: Маркетплейсы | D7: Холодильник.Ру / Шелковый путь | E7: Услуги по продвижению на маркетплейсах: Wildberries | G7: 6000 | H7: =G7/1.22 -> 4918.0328 | I7: 1 | K7: =ROUND(H7*I7,2) -> 4918.03 | M7: =J7+K7-L7 -> 4918.03 | N7: ФИО5 | O7: =M7*8% -> 393.4424 | P7: ФИО1 | Q7: =M7*4% -> 196.7212 | S7: ФИО4
A8: НЛ | B8: Маркетплейсы | C8: Маркетплейсы | D8: ТЕХНОБЕРИНГ | E8: Услуги по продвижению на маркетплейсах: Ozon | G8: 67100 | H8: =G8/1.22 -> 55000 | I8: 1 | K8: =ROUND(H8*I8,2) -> 55000 | M8: =J8+K8-L8 -> 55000 | N8: ФИО7 | O8: =M8*8% -> 4400 | P8: ФИО6 | Q8: =M8*4% -> 2200 | S8: ФИО4
A9: НЛ | B9: Маркетплейсы | C9: Маркетплейсы | D9: ТЕХНОБЕРИНГ | E9: Премия KPI | G9: 71638.32 | H9: =G9/1.22 -> 58719.934 | I9: 1 | K9: =ROUND(H9*I9,2) -> 58719.93 | M9: =J9+K9-L9 -> 58719.93 | N9: ФИО7 | O9: =M9*8% -> 4697.5944 | P9: ФИО6 | Q9: =M9*4% -> 2348.7972 | S9: ФИО4
A10: НЛ | B10: Маркетплейсы | C10: Маркетплейсы | D10: АВ1918 | E10: Услуги по продвижению на маркетплейсах: Ozon | G10: 102000 | H10: =G10/1.22 -> 83606.557 | I10: 1 | K10: =ROUND(H10*I10,2) -> 83606.56 | M10: =J10+K10-L10 -> 83606.56 | N10: ФИО2 | O10: =M10*8% -> 6688.5248 | P10: ФИО2 | Q10: =M10*4% -> 3344.2624 | S10: ФИО4
A11: НЛ | B11: Маркетплейсы | C11: Маркетплейсы | D11: АВ1918 | E11: Услуги по продвижению на маркетплейсах: Ozon | G11: 1700 | H11: =G11/1.22 -> 1393.4426 | I11: 1 | K11: =ROUND(H11*I11,2) -> 1393.44 | M11: =J11+K11-L11 -> 1393.44 | N11: ФИО2 | O11: =M11*8% -> 111.4752 | P11: ФИО2 | Q11: =M11*4% -> 55.7376 | S11: ФИО4
A12: НЛ | B12: Маркетплейсы | C12: Маркетплейсы | D12: АВ1918 | E12: Услуги по продвижению на маркетплейсах: Wildberries | G12: 102000 | H12: =G12/1.22 -> 83606.557 | I12: 1 | K12: =ROUND(H12*I12,2) -> 83606.56 | M12: =J12+K12-L12 -> 83606.56 | N12: ФИО2 | O12: =M12*8% -> 6688.5248 | P12: ФИО2 | Q12: =M12*4% -> 3344.2624 | S12: ФИО4
A13: НЛ | B13: Маркетплейсы | C13: Маркетплейсы | D13: АВ1918 | E13: Услуги по продвижению на маркетплейсах: Wildberries | G13: 1700 | H13: =G13/1.22 -> 1393.4426 | I13: 1 | K13: =ROUND(H13*I13,2) -> 1393.44 | M13: =J13+K13-L13 -> 1393.44 | N13: ФИО2 | O13: =M13*8% -> 111.4752 | P13: ФИО2 | Q13: =M13*4% -> 55.7376 | S13: ФИО4
A14: НЛ | B14: Маркетплейсы | C14: Маркетплейсы | D14: АВ1918 | E14: Услуги по продвижению на маркетплейсах: Яндекс.Маркет | G14: 54000 | H14: =G14/1.22 -> 44262.295 | I14: 1 | K14: =ROUND(H14*I14,2) -> 44262.3 | M14: =J14+K14-L14 -> 44262.3 | N14: ФИО2 | O14: =M14*8% -> 3540.984 | P14: ФИО2 | Q14: =M14*4% -> 1770.492 | S14: ФИО4
A15: НЛ | B15: Маркетплейсы | C15: Маркетплейсы | D15: АВ1918 | E15: Услуги по продвижению на маркетплейсах: Яндекс.Маркет | G15: 900 | H15: =G15/1.22 -> 737.70492 | I15: 1 | K15: =ROUND(H15*I15,2) -> 737.7 | M15: =J15+K15-L15 -> 737.7 | N15: ФИО2 | O15: =M15*8% -> 59.016 | P15: ФИО2 | Q15: =M15*4% -> 29.508 | S15: ФИО4
... A23: SF | B23: Маркетплейсы | C23: Маркетплейсы | D23: Arua | E23: Услуги по продвижению на маркетплейсах: Wildberries | G23: 30603.19 | H23: =G23/1.22 -> 25084.582 | I23: 1 | K23: =ROUND(H23*I23,2) -> 25084.58 | M23: =J23+K23-L23 -> 25084.58 | N23: ФИО5 | O23: =M23*8% -> 2006.7664 | P23: ФИО6 | Q23: =M23*4% -> 1003.3832 | S23: ФИО4
A24: ТЕ | B24: Маркетплейсы | C24: Маркетплейсы | D24: Кудри и любовь | E24: Услуги по продвижению на маркетплейсах: Ozon | G24: 49800 | H24: =G24 -> 49800 | I24: 1 | K24: =ROUND(H24*I24,2) -> 49800 | M24: =J24+K24-L24 -> 49800 | N24: ФИО7 | O24: =M24*8% -> 3984 | P24: ФИО1 | Q24: =M24*4% -> 1992 | S24: ФИО4
A25: ТЕ | B25: Маркетплейсы | C25: Маркетплейсы | D25: Кудри и любовь | E25: Услуги по продвижению на маркетплейсах: Wildberries | G25: 49800 | H25: =G25 -> 49800 | I25: 1 | K25: =ROUND(H25*I25,2) -> 49800 | M25: =J25+K25-L25 -> 49800 | N25: ФИО7 | O25: =M25*8% -> 3984 | P25: ФИО1 | Q25: =M25*4% -> 1992 | S25: ФИО4
D28: ИТОГО | G28: =SUM(G4:G27) -> 1882161.8 | H28: =SUM(H4:H27) -> 1560716.2 | J28: =SUM(J4:J27) -> 0 | K28: =SUM(K4:K27) -> 1560716.2 | L28: =SUM(L4:L27) -> 0 | M28: =SUM(M4:M27) -> 1560716.2 | O28: =SUM(O4:O27) -> 124857.3 | Q28: =SUM(Q4:Q27) -> 62428.648 | V28: =SUM(#REF!) -> #REF! | Y28: =CONCATENATE(D30,E30)
Y29: =CONCATENATE(D47,E47)
Y30: =CONCATENATE(D48,E48)
E32: ФИО2 | G32: =SUMIF(N4:N27,E32,M4:M27) -> 556939.35 | H32: =124742 -> 124742 | I32: =H32/G32 -> 0.22397771
E33: Аббасова | G33: =SUMIF(N4:N27,E33,M4:M27) -> 0 | H33: 65000 | I33: =H33/G33 -> #DIV/0!
E34: ФИО5 | G34: =SUMIF(N4:N27,E34,M4:M27) -> 539349.22 | H34: 89999 | I34: =H34/G34 -> 0.16686591
E36: ФИО3 | G36: =SUMIF(P4:P27,E36,M4:M27) -> 0 | H36: 114368 | I36: =H36/G36 -> #DIV/0!
E37: Беленков | G37: =SUMIF(P4:P27,E37,M4:M27) -> 0 | H37: 86818 | I37: =H37/G37 -> #DIV/0!
E38: ФИО1 | G38: =SUMIF(P4:P27,E38,M4:M27) -> 538864.64 | H38: 100000 | I38: =H38/G38 -> 0.18557536
E39: ФИО6 | G39: =SUMIF(P4:P27,E39,M4:M27) -> 774468.76 | H39: 90000 | I39: =H39/G39 -> 0.11620869
E49: B2basket - сервис размещения рекламы
D50: 0.037 | E50: Яндекс.Маркет
E51: Яндекс.Карты
D52: 0.06 | E52: Яндекс.Маркет проведение рекламной кампании
D53: 0.17 | E53: Google Merchant
D54: 0.12 | E54: Баннер Яндекс.Метро
D55: 1 | E55: Настройка сервиса Cloudflare
E56: Медийное размещение buzzoola
D57: 0.24 | E57: calltouch - инструмент для анализа эффективности рекламы
D58: 0.15 | E58: CoMagiс - инструмент для анализа эффективности рекламы
D59: 0.25 | E59: CoMagiс - инструмент для анализа эффективности рекламы
D60: 1 | E60: Услуги по продвижению на маркетплейсах: Ozon
D61: 1 | E61: UX- рекомендации
...

Sheet Отчет по ЗП
A1: ,
A2: ФОРМУЛЫ НЕ МЕНЯТЬ В ТЕМНЫХ ЯЧЕЙКАХ, ЗАПОЛНЯТЬ ТОЛЬКО ЗЕЛЕНЫЕ, АКТИВИТИ % РЕГУЛИРОВАТЬ ЧЕРЕЗ ЛИСТ ОТЧЕТ ПО МАРЖЕ (Дебиторка и пр)
A4: Группы | C4: ФИО сотрудника | D4: фикс: | E4: Условия % | F4: База % | G4: Менеджер МП | H4: Специалист | I4: активити, %, бонусы | J4: Неснижаемый минимум | K4: прочие доплаты | L4: Отпуск / Больничный / Увольнение | M4: Итого Начислено | N4: выдали 1с
A5: Маркетплейсы | B5: Спец (SF) | C5: ФИО1 | D5: =85000 -> 85000 | G5: =SUMIF('Отчет по марже'!N:N,C5,'Отчет по марже'!O:O) -> 0 | H5: =SUMIF('Отчет по марже'!P:P,C5,'Отчет по марже'!Q:Q) -> 21554.586 | I5: =F5*E5+G5+H5 -> 21554.586 | K5: =85000/120*6*2 -> 8500 | L5: 0 | M5: =D5+I5+L5+J5+K5 -> 115054.59 | N5: 93500
A6: Маркетплейсы | B6: проджект (КА) | C6: ФИО2 | D6: =75000 -> 75000 | G6: =SUMIF('Отчет по марже'!N:N,C6,'Отчет по марже'!O:O) -> 44555.148 | H6: =SUMIF('Отчет по марже'!P:P,C6,'Отчет по марже'!Q:Q) -> 9895.3116 | I6: =F6*E6+G6+H6 -> 54450.46 | K6: =75000/120*2*2 -> 2500 | L6: 0 | M6: =D6+I6+L6+J6+K6 -> 131950.46 | N6: 77500.57
A7: Маркетплейсы | B7: Спец (НЛ) | C7: ФИО3 | D7: =70000/15*5 -> 23333.333 | G7: =SUMIF('Отчет по марже'!N:N,C7,'Отчет по марже'!O:O) -> 0 | H7: =SUMIF('Отчет по марже'!P:P,C7,'Отчет по марже'!Q:Q) -> 0 | I7: =F7*E7+G7+H7 -> 0 | K7: =70000/120*9.5*2 -> 11083.333 | L7: =(21424.5+64273.5)*0.87 -> 74557.26 | M7: =D7+I7+L7+J7+K7 -> 108973.93 | N7: 108973.93
A8: Маркетплейсы | B8: АД маркет (КА) | C8: ФИО4 | D8: =170000 -> 170000 | E8: 0.03 | F8: =SUMIF('Отчет по марже'!S:S,C8,'Отчет по марже'!M:M) -> 1560716.2 | I8: =F8*E8+G8+H8 -> 46821.486 | L8: =62327.23*0.87 -> 54224.69 | M8: =D8+I8+L8+J8+K8 -> 271046.18 | N8: =264589.23-182 -> 264407.23
A9: Маркетплейсы | B9: Проджект (SF) | C9: ФИО5 | D9: =60000 -> 60000 | G9: =SUMIF('Отчет по марже'!N:N,C9,'Отчет по марже'!O:O) -> 43147.938 | H9: =SUMIF('Отчет по марже'!P:P,C9,'Отчет по марже'!Q:Q) -> 0 | I9: =F9*E9+G9+H9 -> 43147.938 | K9: =60000/120*7.3*2 -> 7300 | M9: =D9+I9+L9+J9+K9 -> 110447.94 | N9: 67300.86
A10: Маркетплейсы | B10: Спец (SF) | C10: ФИО6 | D10: =70000/15*11 -> 51333.333 | G10: =SUMIF('Отчет по марже'!N:N,C10,'Отчет по марже'!O:O) -> 0 | H10: =SUMIF('Отчет по марже'!P:P,C10,'Отчет по марже'!Q:Q) -> 30978.75 | I10: =F10*E10+G10+H10 -> 30978.75 | K10: =70000/120*9*2 -> 10500 | L10: 0 | M10: =D10+I10+L10+J10+K10 -> 92812.084 | N10: 61834
A11: Маркетплейсы | B11: Проджект (SF) | C11: ФИО7 | D11: =60000 -> 60000 | G11: =SUMIF('Отчет по марже'!N:N,C11,'Отчет по марже'!O:O) -> 37154.21 | H11: =SUMIF('Отчет по марже'!P:P,C11,'Отчет по марже'!Q:Q) -> 0 | I11: =F11*E11+G11+H11 -> 37154.21 | K11: =60000/120*2*2 -> 2000 | L11: 0 | M11: =D11+I11+L11+J11+K11 -> 99154.21 | N11: 62000.87
D13: =SUM(D5:D12) -> 524666.67 | G13: =SUM(G5:G12) -> 124857.3 | H13: =SUM(H5:H12) -> 62428.648 | I13: =SUM(I5:I12) -> 234107.43 | J13: =SUM(J5:J12) -> 0 | K13: =SUM(K5:K12) -> 41883.333 | L13: =SUM(L5:L12) -> 128781.95 | M13: =SUM(M5:M12) -> 929439.38 | N13: =SUM(N5:N12) -> 735517.46
L15: без НЛ | M15: =M13-M7 -> 820465.45
O34: =AVERAGE(#REF!) -> #REF!

Sheet Динамика сводка
P1: =SUM(P5:P34)/P2 -> 88000 | Q1: =SUM(Q5:Q34)/Q2 -> 83888.082 | BB1: 120 | BC1: 120
P2: =COUNTA(P5:P34) -> 5 | Q2: =COUNTA(Q5:Q34) -> 6
B3: Направление | C3: Январь 2023 | D3: Февраль 2023 | E3: Март 2023 | F3: Апрель 2023 | G3: Май 2023 | H3: Июнь 2023 | I3: Июль 2023 | J3: Август 2023 | K3: Сентябрь 2023 | L3: Октябрь 2023 | M3: Ноябрь 2023 | N3: Декабрь 2023 | O3: Январь 2024 | P3: Февраль 2024 | Q3: Март 2024 | R3: Апрель 2024 | S3: Май 2024 | T3: Июнь 2024 | U3: Июль 2024 | V3: Август 2024 | W3: Сентябрь 2024 | X3: Октябрь 2024 | Y3: Ноябрь 2024 | Z3: Декабрь 2024 | AA3: Январь 2025 | AB3: Февраль 2025 | AC3: Март 2025 | AD3: Апрель 2025 | AE3: Май 2025 | AF3: Июнь 2025 | AG3: Июль 2025 | AH3: Август 2025 | AI3: Сентябрь 2025 | AJ3: Октябрь 2025 | AK3: Ноябрь 2025 | AL3: Декабрь 2025 | AM3: Январь 2026 | AN3: Мес к Мес | AO3: Полгода к полгода | AP3: ИТОГО | AQ3: % месяц | AR3: % LTV | AT3: Средний доход | AV3: Дельта | AW3: Дельта
A4: ЖУКОВСКИЙ | G4: - | H4: - | J4: - | K4: 0 | L4: - | M4: 0 | N4: - | BC4: Срок жизни
A5: Акванет (маркетплейсы) | B5: Маркетплейсы | U5: 125000 | V5: 125000 | W5: 125000 | X5: 125000 | Y5: 125000 | Z5: 125000 | AA5: 125000 | AB5: 89285 | AC5: - | AD5: - | AE5: - | AF5: - | AG5: - | AH5: - | AI5: - | AJ5: - | AK5: - | AL5: - | AM5: =SUMIF('Отчет по марже'!D:D,A5,'Отчет по марже'!M:M) -> 0 | AN5: =AM5-P5 -> 0 | AO5: =SUM(W5:AM5)-SUM(Q5:V5) -> 464285 | AP5: =SUM(C5:AM5) -> 964285 | AQ5: =AM5/$AM$65 -> 0 | AR5: =AP5/$AP$65 -> 0.02572388 | AS5: =AO5/#REF! -> #REF! | AT5: =AVERAGE(C5:AM5) -> 107142.78 | AU5: 117000 | AV5: =#REF!-#REF! -> #REF! | AW5: - 7 418 | AX5: 8 | AY5: =COUNTIF(B5:U5,">0") -> 1 | AZ5: 20 | BC5: =COUNTA($F$5:Q5) -> 0 | BD5: =COUNTA($F5:AA5) -> 7 | BE5: =COUNTA(F5:AA5) -> 7 | BF5: =COUNTA($F5:AA5) -> 7 | BG5: =COUNTA($F5:AM5) -> 19
A6: Холодильник | B6: Маркетплейсы | O6: 31277.71 | P6: 30000 | Q6: 41568.5 | R6: 38356.54 | S6: 58889.94 | T6: 61286.66 | U6: 74336.41 | AB6: - | AC6: - | AD6: - | AE6: - | AF6: - | AG6: - | AH6: - | AI6: - | AJ6: - | AK6: - | AL6: - | AM6: =SUMIF('Отчет по марже'!D:D,A6,'Отчет по марже'!M:M) -> 0 | AN6: =AM6-P6 -> -30000 | AO6: =SUM(W6:AM6)-SUM(Q6:V6) -> -274438.05 | AP6: =SUM(C6:AM6) -> 335715.76 | AQ6: =AM6/$AM$65 -> 0 | AR6: =AP6/$AP$65 -> 0.0089557672 | AS6: =AO6/#REF! -> #REF! | AT6: =AVERAGE(C6:AM6) -> 41964.47 | AV6: =#REF!-#REF! -> #REF! | AW6: - | AY6: =COUNTIF(B6:U6,">0") -> 7 | AZ6: 9 | BC6: =COUNTA(F6:Q6) -> 3 | BD6: =COUNTA($F6:AA6) -> 7 | BE6: =COUNTA(F6:AA6) -> 7 | BF6: =COUNTA($F6:AA6) -> 7 | BG6: =COUNTA($F6:AM6) -> 19
A7: Первый мебельный | B7: Маркетплейсы | T7: 99167 | AB7: - | AC7: - | AD7: - | AE7: - | AF7: - | AG7: - | AH7: - | AI7: - | AJ7: - | AK7: - | AL7: - | AM7: =SUMIF('Отчет по марже'!D:D,A7,'Отчет по марже'!M:M) -> 0 | AN7: =AM7-P7 -> 0 | AO7: =SUM(W7:AM7)-SUM(Q7:V7) -> -99167 | AP7: =SUM(C7:AM7) -> 99167 | AQ7: =AM7/$AM$65 -> 0 | AR7: =AP7/$AP$65 -> 0.002645442 | AS7: =AO7/#REF! -> #REF! | AT7: =AVERAGE(C7:AM7) -> 49583.5 | AU7: 79600 | AV7: =#REF!-#REF! -> #REF! | AW7: - | AX7: 8 | AY7: =COUNTIF(B7:U7,">0") -> 1 | AZ7: 20 | BC7: =COUNTA(F7:Q7) -> 0 | BD7: =COUNTA($F7:AA7) -> 1 | BE7: =COUNTA(F7:AA7) -> 1 | BF7: =COUNTA($F7:AA7) -> 1 | BG7: =COUNTA($F7:AM7) -> 13
A8: SoftSleep | B8: Маркетплейсы | F8: 50000 | G8: 50000 | H8: 86302 | I8: 50000 | J8: 116334 | K8: 111614 | L8: 124739 | M8: 50000 | N8: 50000 | AB8: - | AC8: - | AD8: - | AE8: - | AF8: - | AG8: - | AH8: - | AI8: - | AJ8: - | AK8: - | AL8: - | AM8: =SUMIF('Отчет по марже'!D:D,A8,'Отчет по марже'!M:M) -> 0 | AN8: =AM8-P8 -> 0 | AO8: =SUM(W8:AM8)-SUM(Q8:V8) -> 0 | AP8: =SUM(C8:AM8) -> 688989 | AQ8: =AM8/$AM$65 -> 0 | AR8: =AP8/$AP$65 -> 0.018379909 | AS8: =AO8/#REF! -> #REF! | AT8: =AVERAGE(C8:AM8) -> 68898.9 | AU8: 248000 | AV8: =#REF!-#REF! -> #REF! | AW8: - | AX8: 6 | AY8: =COUNTIF(B8:U8,">0") -> 9 | AZ8: 20 | BC8: =COUNTA(F8:Q8) -> 9 | BD8: =COUNTA($F8:AA8) -> 9 | BE8: =COUNTA(F8:AA8) -> 9 | BF8: =COUNTA($F8:AA8) -> 9 | BG8: =COUNTA($F8:AM8) -> 21
A9: techport.ru | B9: Маркетплейсы | O9: 140000 | AB9: - | AC9: - | AD9: - | AE9: - | AF9: - | AG9: - | AH9: - | AI9: - | AJ9: - | AK9: - | AL9: - | AM9: =SUMIF('Отчет по марже'!D:D,A9,'Отчет по марже'!M:M) -> 0 | AN9: =AM9-P9 -> 0 | AO9: =SUM(W9:AM9)-SUM(Q9:V9) -> 0 | AP9: =SUM(C9:AM9) -> 140000 | AQ9: =AM9/$AM$65 -> 0 | AR9: =AP9/$AP$65 -> 0.0037347291 | AS9: =AO9/#REF! -> #REF! | AT9: =AVERAGE(C9:AM9) -> 70000 | AV9: =#REF!-#REF! -> #REF! | AW9: - | AX9: 5 | AY9: =COUNTIF(B9:U9,">0") -> 1 | AZ9: 16 | BC9: =COUNTA(F9:Q9) -> 1 | BD9: =COUNTA($F9:AA9) -> 1 | BE9: =COUNTA(F9:AA9) -> 1 | BF9: =COUNTA($F9:AA9) -> 1 | BG9: =COUNTA($F9:AM9) -> 13
A10: Son.ru | B10: Маркетплейсы | O10: 30000 | P10: 30000 | Q10: 30000 | R10: 30000 | AB10: - | AC10: - | AD10: - | AE10: - | AF10: - | AG10: - | AH10: - | AI10: - | AJ10: - | AK10: - | AL10: - | AM10: =SUMIF('Отчет по марже'!D:D,A10,'Отчет по марже'!M:M) -> 0 | AN10: =AM10-P10 -> -30000 | AO10: =SUM(W10:AM10)-SUM(Q10:V10) -> -60000 | AP10: =SUM(C10:AM10) -> 120000 | AQ10: =AM10/$AM$65 -> 0 | AR10: =AP10/$AP$65 -> 0.0032011963 | AS10: =AO10/#REF! -> #REF! | AT10: =AVERAGE(C10:AM10) -> 24000 | AV10: =#REF!-#REF! -> #REF! | AW10: - | AX10: 5 | AY10: =COUNTIF(B10:U10,">0") -> 4 | AZ10: 11 | BC10: =COUNTA(F10:Q10) -> 3 | BD10: =COUNTA($F10:AA10) -> 4 | BE10: =COUNTA(F10:AA10) -> 4 | BF10: =COUNTA($F10:AA10) -> 4 | BG10: =COUNTA($F10:AM10) -> 16
A11: Димакс | B11: Маркетплейсы | V11: 120000 | W11: 240000 | X11: 240000 | Y11: 240000 | AB11: - | AC11: - | AD11: - | AE11: - | AF11: - | AG11: - | AH11: - | AI11: - | AJ11: - | AK11: - | AL11: - | AM11: =SUMIF('Отчет по марже'!D:D,A11,'Отчет по марже'!M:M) -> 0 | AN11: =AM11-P11 -> 0 | AO11: =SUM(W11:AM11)-SUM(Q11:V11) -> 600000 | AP11: =SUM(C11:AM11) -> 840000 | AQ11: =AM11/$AM$65 -> 0 | AR11: =AP11/$AP$65 -> 0.022408374 | AS11: =AO11/#REF! -> #REF! | AT11: =AVERAGE(C11:AM11) -> 168000 | AU11: 137500 | AV11: =#REF!-#REF! -> #REF! | AW11: 33 100 | AX11: 6 | AY11: =COUNTIF(B11:U11,">0") -> 0 | AZ11: 20 | BC11: =COUNTA(F11:Q11) -> 0 | BD11: =COUNTA($F11:AA11) -> 4 | BE11: =COUNTA(F11:AA11) -> 4 | BF11: =COUNTA($F11:AA11) -> 4 | BG11: =COUNTA($F11:AM11) -> 16
A12: Моё дело | B12: Маркетплейсы | Z12: 80000 | AB12: - | AC12: - | AD12: - | AE12: - | AF12: - | AG12: - | AH12: - | AI12: - | AJ12: - | AK12: - | AL12: - | AM12: =SUMIF('Отчет по марже'!D:D,A12,'Отчет по марже'!M:M) -> 0 | AN12: =AM12-P12 -> 0 | AO12: =SUM(W12:AM12)-SUM(Q12:V12) -> 80000 | AP12: =SUM(C12:AM12) -> 80000 | AQ12: =AM12/$AM$65 -> 0 | AR12: =AP12/$AP$65 -> 0.0021341309 | AS12: =AO12/#REF! -> #REF! | AT12: =AVERAGE(C12:AM12) -> 40000 | AV12: =#REF!-#REF! -> #REF! | AW12: - | AX12: 5 | AY12: =COUNTIF(B12:U12,">0") -> 0 | AZ12: 12 | BC12: =COUNTA(F12:Q12) -> 0 | BD12: =COUNTA($F12:AA12) -> 1 | BE12: =COUNTA(F12:AA12) -> 1 | BF12: =COUNTA($F12:AA12) -> 1 | BG12: =COUNTA($F12:AM12) -> 13
A13: Jump | B13: Маркетплейсы | C13: 42000 | D13: 50000 | E13: 50000 | F13: 50000 | AB13: - | AC13: - | AD13: - | AE13: - | AF13: - | AG13: - | AH13: - | AI13: - | AJ13: - | AK13: - | AL13: - | AM13: =SUMIF('Отчет по марже'!D:D,A13,'Отчет по марже'!M:M) -> 0 | AN13: =AM13-P13 -> 0 | AO13: =SUM(W13:AM13)-SUM(Q13:V13) -> 0 | AP13: =SUM(C13:AM13) -> 192000 | AQ13: =AM13/$AM$65 -> 0 | AR13: =AP13/$AP$65 -> 0.0051219141 | AS13: =AO13/#REF! -> #REF! | AT13: =AVERAGE(C13:AM13) -> 38400 | AU13: 541000 | AV13: =#REF!-#REF! -> #REF! | AW13: - 503 908 | AX13: 9 | AY13: =COUNTIF(B13:U13,">0") -> 4 | AZ13: 20 | BC13: =COUNTA(F13:Q13) -> 1 | BD13: =COUNTA($F13:AA13) -> 1 | BE13: =COUNTA(F13:AA13) -> 1 | BF13: =COUNTA($F13:AA13) -> 1 | BG13: =COUNTA($F13:AM13) -> 13
A14: Gardenya Home | B14: Маркетплейсы | G14: 82500 | AB14: - | AC14: - | AD14: - | AE14: - | AF14: - | AG14: - | AH14: - | AI14: - | AJ14: - | AK14: - | AL14: - | AM14: =SUMIF('Отчет по марже'!D:D,A14,'Отчет по марже'!M:M) -> 0 | AN14: =AM14-P14 -> 0 | AO14: =SUM(W14:AM14)-SUM(Q14:V14) -> 0 | AP14: =SUM(C14:AM14) -> 82500 | AQ14: =AM14/$AM$65 -> 0 | AR14: =AP14/$AP$65 -> 0.0022008225 | AS14: =AO14/#REF! -> #REF! | AT14: =AVERAGE(C14:AM14) -> 41250 | AV14: =#REF!-#REF! -> #REF! | AW14: - | AX14: 5 | AY14: =COUNTIF(B14:U14,">0") -> 1 | AZ14: 4 | BC14: =COUNTA(F14:Q14) -> 1 | BD14: =COUNTA($F14:AA14) -> 1 | BE14: =COUNTA(F14:AA14) -> 1 | BF14: =COUNTA($F14:AA14) -> 1 | BG14: =COUNTA($F14:AM14) -> 13
A15: TOPTOP.ru | B15: Маркетплейсы | J15: 66667 | K15: 150000 | L15: 200000 | M15: 336867 | N15: 265000 | O15: 220000 | Q15: 118000 | AB15: - | AC15: - | AD15: - | AE15: - | AF15: - | AG15: - | AH15: - | AI15: - | AJ15: - | AK15: - | AL15: - | AM15: =SUMIF('Отчет по марже'!D:D,A15,'Отчет по марже'!M:M) -> 0 | AN15: =AM15-P15 -> 0 | AO15: =SUM(W15:AM15)-SUM(Q15:V15) -> -118000 | AP15: =SUM(C15:AM15) -> 1356534 | AQ15: =AM15/$AM$65 -> 0 | AR15: =AP15/$AP$65 -> 0.036187764 | AS15: =AO15/#REF! -> #REF! | AT15: =AVERAGE(C15:AM15) -> 169566.75 | AU15: 59325 | AV15: =#REF!-#REF! -> #REF! | AW15: - | AX15: 7 | AY15: =COUNTIF(B15:U15,">0") -> 7 | AZ15: 18 | BC15: =COUNTA(F15:Q15) -> 7 | BD15: =COUNTA($F15:AA15) -> 7 | BE15: =COUNTA(F15:AA15) -> 7 | BF15: =COUNTA($F15:AA15) -> 7 | BG15: =COUNTA($F15:AM15) -> 19
A16: Massi | B16: Маркетплейсы | L16: 40000 | M16: 60000 | N16: 60000 | O16: 90000 | P16: 150000 | AB16: - | AC16: - | AD16: - | AE16: - | AF16: - | AG16: - | AH16: - | AI16: - | AJ16: - | AK16: - | AL16: - | AM16: =SUMIF('Отчет по марже'!D:D,A16,'Отчет по марже'!M:M) -> 0 | AN16: =AM16-P16 -> -150000 | AO16: =SUM(W16:AM16)-SUM(Q16:V16) -> 0 | AP16: =SUM(C16:AM16) -> 400000 | AQ16: =AM16/$AM$65 -> 0 | AR16: =AP16/$AP$65 -> 0.010670654 | AS16: =AO16/#REF! -> #REF! | AT16: =AVERAGE(C16:AM16) -> 66666.667 | AU16: 259000 | AV16: =#REF!-#REF! -> #REF! | AW16: - 48 850 | AX16: 9 | AY16: =COUNTIF(B16:U16,">0") -> 5 | AZ16: 17 | BC16: =COUNTA(F16:Q16) -> 5 | BD16: =COUNTA($F16:AA16) -> 5 | BE16: =COUNTA(F16:AA16) -> 5 | BF16: =COUNTA($F16:AA16) -> 5 | BG16: =COUNTA($F16:AM16) -> 17
A17: Ivideon маркетплейсы | B17: Маркетплейсы | M17: 26000 | N17: 48541 | O17: -5800 | AB17: - | AC17: - | AD17: - | AE17: - | AF17: - | AG17: - | AH17: - | AI17: - | AJ17: - | AK17: - | AL17: - | AM17: =SUMIF('Отчет по марже'!D:D,A17,'Отчет по марже'!M:M) -> 0 | AN17: =AM17-P17 -> 0 | AO17: =SUM(W17:AM17)-SUM(Q17:V17) -> 0 | AP17: =SUM(C17:AM17) -> 68741 | AQ17: =AM17/$AM$65 -> 0 | AR17: =AP17/$AP$65 -> 0.0018337786 | AS17: =AO17/#REF! -> #REF! | AT17: =AVERAGE(C17:AM17) -> 17185.25 | AV17: =#REF!-#REF! -> #REF! | AW17: - | AX17: 5 | AY17: =COUNTIF(B17:U17,">0") -> 2 | AZ17: 10 | BC17: =COUNTA(F17:Q17) -> 3 | BD17: =COUNTA($F17:AA17) -> 3 | BE17: =COUNTA(F17:AA17) -> 3 | BF17: =COUNTA($F17:AA17) -> 3 | BG17: =COUNTA($F17:AM17) -> 15
A18: Zenden | B18: Маркетплейсы | M18: 200000 | N18: 200000 | O18: 198000 | P18: 200000 | Q18: 200000 | R18: 200000 | S18: 200000 | T18: 200000 | U18: 150000 | V18: 204167 | W18: 200000 | X18: 200000 | Y18: 200000 | Z18: 200000 | AA18: 100000 | AB18: 200000 | AC18: - | AD18: - | AE18: - | AF18: - | AG18: - | AH18: - | AI18: - | AJ18: - | AK18: - | AL18: - | AM18: =SUMIF('Отчет по марже'!D:D,A18,'Отчет по марже'!M:M) -> 0 | AN18: =AM18-P18 -> -200000 | AO18: =SUM(W18:AM18)-SUM(Q18:V18) -> -54167 | AP18: =SUM(C18:AM18) -> 3052167 | AQ18: =AM18/$AM$65 -> 0 | AR18: =AP18/$AP$65 -> 0.081421549 | AS18: =AO18/#REF! -> #REF! | AT18: =AVERAGE(C18:AM18) -> 179539.24 | AV18: =#REF!-#REF! -> #REF! | AW18: - | AX18: 5 | AY18: =COUNTIF(B18:U18,">0") -> 9 | AZ18: 4 | BC18: =COUNTA(F18:Q18) -> 5 | BD18: =COUNTA($F18:AA18) -> 15 | BE18: =COUNTA(F18:AA18) -> 15 | BF18: =COUNTA($F18:AA18) -> 15 | BG18: =COUNTA($F18:AM18) -> 27
A19: Хлеб и Торты (Черемушки) | B19: Маркетплейсы | O19: 31327.77 | P19: 30000 | Q19: 30426.99 | AB19: - | AC19: - | AD19: - | AE19: - | AF19: - | AG19: - | AH19: - | AI19: - | AJ19: - | AK19: - | AL19: - | AM19: =SUMIF('Отчет по марже'!D:D,A19,'Отчет по марже'!M:M) -> 0 | AN19: =AM19-P19 -> -30000 | AO19: =SUM(W19:AM19)-SUM(Q19:V19) -> -30426.99 | AP19: =SUM(C19:AM19) -> 91754.76 | AQ19: =AM19/$AM$65 -> 0 | AR19: =AP19/$AP$65 -> 0.0024477083 | AT19: =AVERAGE(C19:AM19) -> 22938.69 | AU19: 200000 | AV19: =#REF!-#REF! -> #REF! | AW19: 100 000 | AX19: 5 | AY19: =COUNTIF(B19:U19,">0") -> 3 | AZ19: 12 | BC19: =COUNTA(F19:Q19) -> 3 | BD19: =COUNTA($F19:AA19) -> 3 | BE19: =COUNTA(F19:AA19) -> 3 | BF19: =COUNTA($F19:AA19) -> 3 | BG19: =COUNTA($F19:AM19) -> 15
A20: Haier | B20: Маркетплейсы | V20: 116666.67 | W20: 46666.67 | X20: 46666.67 | Y20: -11786.07 | AB20: - | AC20: - | AD20: - | AE20: - | AF20: - | AG20: - | AH20: - | AI20: - | AJ20: - | AK20: - | AL20: - | AM20: =SUMIF('Отчет по марже'!D:D,A20,'Отчет по марже'!M:M) -> 0 | AN20: =AM20-P20 -> 0 | AO20: =SUM(W20:AM20)-SUM(Q20:V20) -> -35119.4 | AP20: =SUM(C20:AM20) -> 198213.94 | AQ20: =AM20/$AM$65 -> 0 | AR20: =AP20/$AP$65 -> 0.0052876812 | AT20: =AVERAGE(C20:AM20) -> 39642.788 | AU20: 194583 | AV20: =#REF!-#REF! -> #REF! | AW20: - 69 210 | AX20: 7 | AY20: =COUNTIF(B20:U20,">0") -> 0 | AZ20: 13 | BC20: =COUNTA(F20:Q20) -> 0 | BD20: =COUNTA($F20:AA20) -> 4 | BE20: =COUNTA(F20:AA20) -> 4 | BF20: =COUNTA($F20:AA20) -> 4 | BG20: =COUNTA($F20:AM20) -> 16
A21: Homfort | B21: Маркетплейсы | Q21: 83333 | R21: 100000 | U21: 100000 | V21: 100000 | W21: 100000 | X21: 100000 | Y21: 100000 | AB21: - | AC21: - | AD21: - | AE21: - | AF21: - | AG21: - | AH21: - | AI21: - | AJ21: - | AK21: - | AL21: - | AM21: =SUMIF('Отчет по марже'!D:D,A21,'Отчет по марже'!M:M) -> 0 | AN21: =AM21-P21 -> 0 | AO21: =SUM(W21:AM21)-SUM(Q21:V21) -> -83333 | AP21: =SUM(C21:AM21) -> 683333 | AQ21: =AM21/$AM$65 -> 0 | AR21: =AP21/$AP$65 -> 0.018229026 | AT21: =AVERAGE(C21:AM21) -> 85416.625 | AU21: 102000 | AV21: =#REF!-#REF! -> #REF! | AW21: - | AX21: 7 | AY21: =COUNTIF(B21:U21,">0") -> 3 | AZ21: 13 | BC21: =COUNTA(F21:Q21) -> 1 | BD21: =COUNTA($F21:AA21) -> 7 | BE21: =COUNTA(F21:AA21) -> 7 | BF21: =COUNTA($F21:AA21) -> 7 | BG21: =COUNTA($F21:AM21) -> 19
A22: HomeKitchen | B22: Маркетплейсы | R22: 108333 | S22: 100000 | T22: 100000 | AB22: - | AC22: - | AD22: - | AE22: - | AF22: - | AG22: - | AH22: - | AI22: - | AJ22: - | AK22: - | AL22: - | AM22: =SUMIF('Отчет по марже'!D:D,A22,'Отчет по марже'!M:M) -> 0 | AN22: =AM22-P22 -> 0 | AO22: =SUM(W22:AM22)-SUM(Q22:V22) -> -308333 | AP22: =SUM(C22:AM22) -> 308333 | AQ22: =AM22/$AM$65 -> 0 | AR22: =AP22/$AP$65 -> 0.0082252873 | AT22: =AVERAGE(C22:AM22) -> 77083.25 | AV22: =#REF!-#REF! -> #REF! | AW22: - | AY22: =COUNTIF(B22:U22,">0") -> 3 | AZ22: 3 | BC22: =COUNTA(F22:Q22) -> 0 | BD22: =COUNTA($F22:AA22) -> 3 | BE22: =COUNTA(F22:AA22) -> 3 | BF22: =COUNTA($F22:AA22) -> 3 | BG22: =COUNTA($F22:AM22) -> 15
A23: Samba | B23: Маркетплейсы | R23: 220000 | AB23: - | AC23: - | AD23: - | AE23: - | AF23: - | AG23: - | AH23: - | AI23: - | AJ23: - | AK23: - | AL23: - | AM23: =SUMIF('Отчет по марже'!D:D,A23,'Отчет по марже'!M:M) -> 0 | AN23: =AM23-P23 -> 0 | AO23: =SUM(W23:AM23)-SUM(Q23:V23) -> -220000 | AP23: =SUM(C23:AM23) -> 220000 | AQ23: =AM23/$AM$65 -> 0 | AR23: =AP23/$AP$65 -> 0.00586886 | AT23: =AVERAGE(C23:AM23) -> 110000 | AU23: 102000 | AV23: =#REF!-#REF! -> #REF! | AW23: - | AX23: 4 | AY23: =COUNTIF(B23:U23,">0") -> 1 | AZ23: 10 | BC23: =COUNTA(F23:Q23) -> 0 | BD23: =COUNTA($F23:AA23) -> 1 | BE23: =COUNTA(F23:AA23) -> 1 | BF23: =COUNTA($F23:AA23) -> 1 | BG23: =COUNTA($F23:AM23) -> 13
A24: BOXY | B24: Маркетплейсы | S24: 110000 | T24: 110000 | U24: 110000 | V24: 110000 | W24: 110000 | X24: 110000 | Y24: 110000 | Z24: 110000 | AA24: 110000 | AB24: 110000 | AC24: - | AD24: - | AE24: - | AF24: - | AG24: - | AH24: - | AI24: - | AJ24: - | AK24: - | AL24: - | AM24: =SUMIF('Отчет по марже'!D:D,A24,'Отчет по марже'!M:M) -> 0 | AN24: =AM24-P24 -> 0 | AO24: =SUM(W24:AM24)-SUM(Q24:V24) -> 220000 | AP24: =SUM(C24:AM24) -> 1100000 | AQ24: =AM24/$AM$65 -> 0 | AR24: =AP24/$AP$65 -> 0.0293443 | AT24: =AVERAGE(C24:AM24) -> 100000 | AU24: 93000 | AV24: =#REF!-#REF! -> #REF! | AW24: - | AX24: 5 | AY24: =COUNTIF(B24:U24,">0") -> 3 | AZ24: 8 | BC24: =COUNTA(F24:Q24) -> 0 | BD24: =COUNTA($F24:AA24) -> 9 | BE24: =COUNTA(F24:AA24) -> 9 | BF24: =COUNTA($F24:AA24) -> 9 | BG24: =COUNTA($F24:AM24) -> 21
A25: Natura Siberica | B25: Маркетплейсы | S25: 335500 | AB25: - | AC25: - | AD25: - | AE25: - | AF25: - | AG25: - | AH25: - | AI25: - | AJ25: - | AK25: - | AL25: - | AM25: =SUMIF('Отчет по марже'!D:D,A25,'Отчет по марже'!M:M) -> 0 | AN25: =AM25-P25 -> 0 | AO25: =SUM(W25:AM25)-SUM(Q25:V25) -> -335500 | AP25: =SUM(C25:AM25) -> 335500 | AQ25: =AM25/$AM$65 -> 0 | AR25: =AP25/$AP$65 -> 0.0089500114 | AT25: =AVERAGE(C25:AM25) -> 167750 | AU25: 131000 | AV25: =#REF!-#REF! -> #REF! | AW25: - | AX25: 5 | AY25: =COUNTIF(B25:U25,">0") -> 1 | AZ25: 8 | BC25: =COUNTA(F25:Q25) -> 0 | BD25: =COUNTA($F25:AA25) -> 1 | BE25: =COUNTA(F25:AA25) -> 1 | BF25: =COUNTA($F25:AA25) -> 1 | BG25: =COUNTA($F25:AM25) -> 13
A26: Soho | B26: Маркетплейсы | S26: 233333 | V26: 233333 | W26: 116667 | X26: 184409 | Y26: 233333.33 | Z26: 341666.67 | AA26: 300000 | AB26: 300000 | AC26: - | AD26: - | AE26: - | AF26: - | AG26: - | AH26: - | AI26: - | AJ26: - | AK26: - | AL26: - | AM26: =SUMIF('Отчет по марже'!D:D,A26,'Отчет по марже'!M:M) -> 0 | AN26: =AM26-P26 -> 0 | AO26: =SUM(W26:AM26)-SUM(Q26:V26) -> 1009410 | AP26: =SUM(C26:AM26) -> 1942742 | AQ26: =AM26/$AM$65 -> 0 | AR26: =AP26/$AP$65 -> 0.051825821 | AT26: =AVERAGE(C26:AM26) -> 215860.22 | AU26: 40000 | AV26: =#REF!-#REF! -> #REF! | AW26: - | AX26: 5 | AY26: =COUNTIF(B26:U26,">0") -> 1 | AZ26: 5 | BC26: =COUNTA(F26:Q26) -> 0 | BD26: =COUNTA($F26:AA26) -> 7 | BE26: =COUNTA(F26:AA26) -> 7 | BF26: =COUNTA($F26:AA26) -> 7 | BG26: =COUNTA($F26:AM26) -> 19
A27: Сладкая Сказка | B27: Маркетплейсы | S27: 94333 | AB27: - | AC27: - | AD27: - | AE27: - | AF27: - | AG27: - | AH27: - | AI27: - | AJ27: - | AK27: - | AL27: - | AM27: =SUMIF('Отчет по марже'!D:D,A27,'Отчет по марже'!M:M) -> 0 | AN27: =AM27-P27 -> 0 | AO27: =SUM(W27:AM27)-SUM(Q27:V27) -> -94333 | AP27: =SUM(C27:AM27) -> 94333 | AQ27: =AM27/$AM$65 -> 0 | AR27: =AP27/$AP$65 -> 0.0025164871 | AT27: =AVERAGE(C27:AM27) -> 47166.5 | AV27: =#REF!-#REF! -> #REF! | AW27: - | AY27: =COUNTIF(B27:U27,">0") -> 1 | AZ27: 1 | BC27: =COUNTA(F27:Q27) -> 0 | BD27: =COUNTA($F27:AA27) -> 1 | BE27: =COUNTA(F27:AA27) -> 1 | BF27: =COUNTA($F27:AA27) -> 1 | BG27: =COUNTA($F27:AM27) -> 13
A28: Клуб мастеров | B28: Маркетплейсы | T28: 111667 | U28: 708333 | V28: 663333 | AB28: - | AC28: - | AD28: - | AE28: - | AF28: - | AG28: - | AH28: - | AI28: - | AJ28: - | AK28: - | AL28: - | AM28: =SUMIF('Отчет по марже'!D:D,A28,'Отчет по марже'!M:M) -> 0 | AN28: =AM28-P28 -> 0 | AO28: =SUM(W28:AM28)-SUM(Q28:V28) -> -1483333 | AP28: =SUM(C28:AM28) -> 1483333 | AQ28: =AM28/$AM$65 -> 0 | AR28: =AP28/$AP$65 -> 0.039570335 | AT28: =AVERAGE(C28:AM28) -> 370833.25 | AU28: 90000 | AV28: =#REF!-#REF! -> #REF! | AW28: 89 703 | AX28: 7 | AY28: =COUNTIF(B28:U28,">0") -> 2 | AZ28: 9 | BC28: =COUNTA(F28:Q28) -> 0 | BD28: =COUNTA($F28:AA28) -> 3 | BE28: =COUNTA(F28:AA28) -> 3 | BF28: =COUNTA($F28:AA28) -> 3 | BG28: =COUNTA($F28:AM28) -> 15
A29: ВИНК | B29: Маркетплейсы | U29: 181250 | AB29: - | AC29: - | AD29: - | AE29: - | AF29: - | AG29: - | AH29: - | AI29: - | AJ29: - | AK29: - | AL29: - | AM29: =SUMIF('Отчет по марже'!D:D,A29,'Отчет по марже'!M:M) -> 0 | AN29: =AM29-P29 -> 0 | AO29: =SUM(W29:AM29)-SUM(Q29:V29) -> -181250 | AP29: =SUM(C29:AM29) -> 181250 | AQ29: =AM29/$AM$65 -> 0 | AR29: =AP29/$AP$65 -> 0.0048351403 | AT29: =AVERAGE(C29:AM29) -> 90625 | AU29: 193781 | AV29: =#REF!-#REF! -> #REF! | AW29: - | AX29: 10 | AY29: =COUNTIF(B29:U29,">0") -> 1 | AZ29: 7 | BC29: =COUNTA(F29:Q29) -> 0 | BD29: =COUNTA($F29:AA29) -> 1 | BE29: =COUNTA(F29:AA29) -> 1 | BF29: =COUNTA($F29:AA29) -> 1 | BG29: =COUNTA($F29:AM29) -> 13
A30: Супрэмо | B30: Маркетплейсы | V30: 70000 | W30: 140000 | X30: 140000 | Y30: 140000 | Z30: 140000 | AB30: - | AC30: - | AD30: - | AE30: - | AF30: - | AG30: - | AH30: - | AI30: - | AJ30: - | AK30: - | AL30: - | AM30: =SUMIF('Отчет по марже'!D:D,A30,'Отчет по марже'!M:M) -> 0 | AN30: =AM30-P30 -> 0 | AO30: =SUM(W30:AM30)-SUM(Q30:V30) -> 490000 | AP30: =SUM(C30:AM30) -> 630000 | AQ30: =AM30/$AM$65 -> 0 | AR30: =AP30/$AP$65 -> 0.016806281 | AT30: =AVERAGE(C30:AM30) -> 105000 | AV30: =#REF!-#REF! -> #REF! | AW30: - | AY30: =COUNTIF(B30:U30,">0") -> 0 | AZ30: 3 | BC30: =COUNTA(F30:Q30) -> 0 | BD30: =COUNTA($F30:AA30) -> 5 | BE30: =COUNTA(F30:AA30) -> 5 | BF30: =COUNTA($F30:AA30) -> 5 | BG30: =COUNTA($F30:AM30) -> 17
A31: Polaris | B31: Маркетплейсы | X31: 150000 | Y31: 150000 | Z31: 233333.33 | AA31: 400000 | AB31: 400000 | AC31: 400000 | AD31: 400000 | AE31: 400000 | AF31: 308333 | AG31: 308333 | AH31: - | AI31: - | AJ31: - | AK31: - | AL31: - | AM31: =SUMIF('Отчет по марже'!D:D,A31,'Отчет по марже'!M:M) -> 0 | AN31: =AM31-P31 -> 0 | AO31: =SUM(W31:AM31)-SUM(Q31:V31) -> 3149999.3 | AP31: =SUM(C31:AM31) -> 3149999.3 | AQ31: =AM31/$AM$65 -> 0 | AR31: =AP31/$AP$65 -> 0.084031386 | AT31: =AVERAGE(C31:AM31) -> 286363.58 | AV31: =#REF!-#REF! -> #REF! | AW31: - | AY31: =COUNTIF(B31:U31,">0") -> 0 | AZ31: 1 | BC31: =COUNTA(F31:Q31) -> 0 | BD31: =COUNTA($F31:AA31) -> 4 | BE31: =COUNTA(F31:AA31) -> 4 | BF31: =COUNTA($F31:AA31) -> 4 | BG31: =COUNTA($F31:AM31) -> 16
A32: Табурет | B32: Маркетплейсы | X32: 70000 | Y32: 140000 | Z32: 140000 | AA32: 140000 | AB32: 140000 | AC32: - | AD32: - | AE32: - | AF32: - | AG32: - | AH32: - | AI32: - | AJ32: - | AK32: - | AL32: - | AM32: =SUMIF('Отчет по марже'!D:D,A32,'Отчет по марже'!M:M) -> 0 | AN32: =AM32-P32 -> 0 | AO32: =SUM(W32:AM32)-SUM(Q32:V32) -> 630000
A33: Ceramica Nova | B33: Маркетплейсы | Y33: 139166.67 | AB33: - | AC33: - | AD33: - | AE33: - | AF33: - | AG33: - | AH33: - | AI33: - | AJ33: - | AK33: - | AL33: - | AM33: =SUMIF('Отчет по марже'!D:D,A33,'Отчет по марже'!M:M) -> 0 | AN33: =AM33-P33 -> 0 | AO33: =SUM(W33:AM33)-SUM(Q33:V33) -> 139166.67 | AP33: =SUM(C33:AM33) -> 139166.67 | AQ33: =AM33/$AM$65 -> 0 | AR33: =AP33/$AP$65 -> 0.0037124986 | AT33: =AVERAGE(C33:AM33) -> 69583.335 | AV33: =#REF!-#REF! -> #REF! | AW33: - | AY33: =COUNTIF(B33:U33,">0") -> 0 | AZ33: 1 | BC33: =COUNTA(F33:Q33) -> 0 | BD33: =COUNTA($F33:AA33) -> 1 | BE33: =COUNTA(F33:AA33) -> 1 | BF33: =COUNTA($F33:AA33) -> 1 | BG33: =COUNTA($F33:AM33) -> 13
A34: Феликс | B34: Маркетплейсы | Y34: 62500 | AB34: - | AC34: - | AD34: - | AE34: - | AF34: - | AG34: - | AH34: - | AI34: - | AJ34: - | AK34: - | AL34: - | AM34: =SUMIF('Отчет по марже'!D:D,A34,'Отчет по марже'!M:M) -> 0 | AN34: =AM34-P34 -> 0 | AO34: =SUM(W34:AM34)-SUM(Q34:V34) -> 62500 | AP34: =SUM(C34:AM34) -> 62500 | AQ34: =AM34/$AM$65 -> 0 | AR34: =AP34/$AP$65 -> 0.0016672898 | AT34: =AVERAGE(C34:AM34) -> 31250 | AV34: =#REF!-#REF! -> #REF! | AW34: - | AY34: =COUNTIF(B34:U34,">0") -> 0 | AZ34: 2 | BC34: =COUNTA(F34:Q34) -> 0 | BD34: =COUNTA($F34:AA34) -> 1 | BE34: =COUNTA(F34:AA34) -> 1 | BF34: =COUNTA($F34:AA34) -> 1 | BG34: =COUNTA($F34:AM34) -> 13
A35: ANI PLAST | B35: Маркетплейсы | AC35: 391408 | AD35: 417528 | AE35: 414756 | AF35: 357400 | AG35: 389425 | AH35: 355024 | AI35: 282839 | AJ35: 293555 | AK35: 261588 | AL35: 199887 | AM35: =SUMIF('Отчет по марже'!D:D,A35,'Отчет по марже'!M:M) -> 0 | AN35: =AM35-P35 -> 0 | AO35: =SUM(W35:AM35)-SUM(Q35:V35) -> 3363410 | AP35: =SUM(C35:AM35) -> 3363410 | AQ35: =AM35/$AM$65 -> 0 | AR35: =AP35/$AP$65 -> 0.089724465 | AT35: =AVERAGE(C35:AM35) -> 305764.55 | AV35: =#REF!-#REF! -> #REF! | AW35: -
A36: спецмазь | B36: Маркетплейсы | AC36: 138691 | AD36: - | AE36: - | AF36: - | AG36: - | AH36: - | AI36: - | AJ36: - | AK36: - | AL36: - | AM36: =SUMIF('Отчет по марже'!D:D,A36,'Отчет по марже'!M:M) -> 0 | AN36: =AM36-P36 -> 0 | AO36: =SUM(W36:AM36)-SUM(Q36:V36) -> 138691 | AP36: =SUM(C36:AM36) -> 138691 | AQ36: =AM36/$AM$65 -> 0 | AR36: =AP36/$AP$65 -> 0.0036998093 | AT36: =AVERAGE(C36:AM36) -> 69345.5 | AV36: =#REF!-#REF! -> #REF! | AW36: -
A37: шустерс | B37: Маркетплейсы | AC37: 45600 | AD37: - | AE37: - | AF37: - | AG37: - | AH37: - | AI37: - | AJ37: - | AK37: - | AL37: - | AM37: =SUMIF('Отчет по марже'!D:D,A37,'Отчет по марже'!M:M) -> 0 | AN37: =AM37-P37 -> 0 | AO37: =SUM(W37:AM37)-SUM(Q37:V37) -> 45600 | AP37: =SUM(C37:AM37) -> 45600 | AQ37: =AM37/$AM$65 -> 0 | AR37: =AP37/$AP$65 -> 0.0012164546 | AT37: =AVERAGE(C37:AM37) -> 22800 | AV37: =#REF!-#REF! -> #REF! | AW37: -
A38: ТЕХНОБЕРИНГ | B38: Маркетплейсы | AC38: 62185 | AD38: 75088 | AE38: 78306 | AF38: 71197 | AG38: 87148 | AH38: 103235 | AI38: 104827 | AJ38: 122542 | AK38: 133461 | AL38: 128651 | AM38: =SUMIF('Отчет по марже'!D:D,A38,'Отчет по марже'!M:M) -> 113719.93 | AN38: =AM38-P38 -> 113719.93 | AO38: =SUM(W38:AM38)-SUM(Q38:V38) -> 1080359.9 | AP38: =SUM(C38:AM38) -> 1080359.9 | AQ38: =AM38/$AM$65 -> 0.072863939 | AR38: =AP38/$AP$65 -> 0.028820369 | AT38: =AVERAGE(C38:AM38) -> 98214.539 | AV38: =#REF!-#REF! -> #REF! | AW38: -
A39: ИП СЕМЕНОВА Е.В. | B39: Маркетплейсы | AC39: 86158 | AD39: - | AE39: - | AF39: - | AG39: - | AH39: - | AI39: - | AJ39: - | AK39: - | AL39: - | AM39: =SUMIF('Отчет по марже'!D:D,A39,'Отчет по марже'!M:M) -> 0 | AN39: =AM39-P39 -> 0 | AO39: =SUM(W39:AM39)-SUM(Q39:V39) -> 86158 | AP39: =SUM(C39:AM39) -> 86158 | AQ39: =AM39/$AM$65 -> 0 | AR39: =AP39/$AP$65 -> 0.0022984056 | AT39: =AVERAGE(C39:AM39) -> 43079 | AV39: =#REF!-#REF! -> #REF! | AW39: -
A40: ООО АВК | B40: Маркетплейсы | AC40: 234707 | AD40: - | AE40: - | AF40: - | AG40: - | AH40: - | AI40: - | AJ40: - | AK40: - | AL40: - | AM40: =SUMIF('Отчет по марже'!D:D,A40,'Отчет по марже'!M:M) -> 0 | AN40: =AM40-P40 -> 0 | AO40: =SUM(W40:AM40)-SUM(Q40:V40) -> 234707 | AP40: =SUM(C40:AM40) -> 234707 | AQ40: =AM40/$AM$65 -> 0 | AR40: =AP40/$AP$65 -> 0.0062611932 | AT40: =AVERAGE(C40:AM40) -> 117353.5 | AV40: =#REF!-#REF! -> #REF! | AW40: -
...
